## 异步 & 事件循环

### 1

```js
const promise = new Promise((resolve, reject) => {
  console.log(1);
  console.log(2);
});
promise.then(() => {
  console.log(3);
});
console.log(4);
```

```js
1
2
4
```

>promise.then 是微任务，它会在所有的宏任务执行完之后才会执行，同时需要 promise 内部的状态发生变化，因为这里内部没有发生变化，一直处于 pending 状态，所以不输出 3。

### 2

```js
const promise1 = new Promise((resolve, reject) => {
  console.log('promise1')
  resolve('resolve1')
})
const promise2 = promise1.then(res => {
  console.log(res)
})
console.log('1', promise1);
console.log('2', promise2);
```

```js
promise1
1 Promise{<resolved>: resolve1}
2 Promise{<pending>}
resolve1
```

>直接打印 promise，会打印出它的状态值和参数。

1. script 是一个宏任务，按照顺序执行这些代码；
2. 首先进入 Promise，执行该构造函数中的代码，打印 `promise1`；
3. 碰到 `resolve` 函数, 将 `promise1` 的状态改变为 `resolved`, 并将结果保存下来；
4. 碰到 `promise1.then` 这个微任务，将它放入微任务队列；
5. `promise2` 是一个新的状态为 `pending` 的 `Promise`；
6. 执行同步代码 1， 同时打印出 `promise1` 的状态是 `resolved`；
7. 执行同步代码 2，同时打印出 `promise2` 的状态是 `pending`；
8. 宏任务执行完毕，查找微任务队列，发现 `promise1.then` 这个微任务且状态为 `resolved`，执行它。

### 3

```js
const promise = new Promise((resolve, reject) => {
  console.log(1);
  setTimeout(() => {
    console.log("timerStart");
    resolve("success");
    console.log("timerEnd");
  }, 0);
  console.log(2);
});
promise.then((res) => {
  console.log(res);
});
console.log(4);
```

```js
1
2
4
timerStart
timerEnd
success
```

1. 首先遇到 Promise 构造函数，会先执行里面的内容，打印 `1`；
2. 遇到定时器 `steTimeout`，它是一个宏任务，放入宏任务队列；
3. 继续向下执行，打印出 2；
4. 由于 `Promise` 的状态此时还是 `pending`，所以 `promise.then` 先不执行；
5. 继续执行下面的同步任务，打印出 4；
6. 此时微任务队列没有任务，继续执行下一轮宏任务，执行 `steTimeout`；
7. 首先执行 `timerStart`，然后遇到了 `resolve`，将 `promise` 的状态改为 `resolved` 且保存结果并将之前的 `promise.then` 推入微任务队列，再执行 `timerEnd`；
8. 执行完这个宏任务，就去执行微任务 `promise.then`，打印出 `resolve` 的结果。

### 4

```js
Promise.resolve().then(() => {
  console.log('promise1');
  const timer2 = setTimeout(() => {
    console.log('timer2')
  }, 0)
});
const timer1 = setTimeout(() => {
  console.log('timer1')
  Promise.resolve().then(() => {
    console.log('promise2')
  })
}, 0)
console.log('start');
```

```js
start
promise1
timer1
promise2
timer2
```

1. 首先，`Promise.resolve().then` 是一个微任务，加入微任务队列
2. 执行 timer1，它是一个宏任务，加入宏任务队列
3. 继续执行下面的同步代码，打印出 `start`
4. 这样第一轮宏任务就执行完了，开始执行微任务 `Promise.resolve().then`，打印出 `promise1`
5. 遇到 `timer2`，它是一个宏任务，将其加入宏任务队列，此时宏任务队列有两个任务，分别是 `timer1`、`timer2`；
6. 这样第一轮微任务就执行完了，开始执行第二轮宏任务，首先执行定时器 `timer1`，打印 `timer1`；
7. 遇到 `Promise.resolve().then`，它是一个微任务，加入微任务队列
8. 开始执行微任务队列中的任务，打印 `promise2`；
9. 最后执行宏任务 `timer2` 定时器，打印出 `timer2`；

### 5

```js
const promise = new Promise((resolve, reject) => {
    resolve('success1');
    reject('error');
    resolve('success2');
});
promise.then((res) => {
    console.log('then:', res);
}).catch((err) => {
    console.log('catch:', err);
})
```

```js
then：success1
```

> **Promise 的状态在发生变化之后，就不会再发生变化**。开始状态由 `pending` 变为 `resolve`，说明已经变为已完成状态，下面的两个状态的就不会再执行，同时下面的 catch 也不会捕获到错误。

### 6

```js
Promise.resolve(1)
  .then(2)
  .then(Promise.resolve(3))
  .then(console.log)
```

```js
1
```

> `.then` 或 `.catch` 的参数期望是函数，传入非函数则会发生**值透传**。

### 7

```js
const promise1 = new Promise((resolve, reject) => {
  setTimeout(() => {
    resolve('success')
  }, 1000)
})
const promise2 = promise1.then(() => {
  throw new Error('error!!!')
})
console.log('promise1', promise1)
console.log('promise2', promise2)
setTimeout(() => {
  console.log('promise1', promise1)
  console.log('promise2', promise2)
}, 2000)
```

```js
promise1 Promise {<pending>}
promise2 Promise {<pending>}

Uncaught (in promise) Error: error!!!
promise1 Promise {<fulfilled>: "success"}
promise2 Promise {<rejected>: Error: error!!}
```

### 8

```js
Promise.resolve(1)
  .then((res) => {
    console.log(res);
    return 2;
  })
  .catch((err) => {
    return 3;
  })
  .then((res) => {
    console.log(res);
  });
```

```js
1   
2
```

> Promise 是可以链式调用的，由于每次调用 `.then` 或者 `.catch` 都会返回一个新的 promise，从而实现了链式调用, 它并不像一般任务的链式调用一样 return this。
>
> 上面的输出结果之所以依次打印出 1 和 2，是因为 `resolve(1)` 之后走的是第一个 then 方法，并没有进 catch 里，所以第二个 then 中的 res 得到的实际上是第一个 then 的返回值。并且 return 2 会被包装成 `resolve(2)`，被最后的 then 打印输出 2。

### 9

```js
Promise.resolve().then(() => {
  return new Error('error!!!')
}).then(res => {
  console.log("then: ", res)
}).catch(err => {
  console.log("catch: ", err)
})
```

```js
"then: " "Error: error!!!"
```

> 返回任意一个非 promise 的值都会被包裹成 promise 对象，因此这里的 `return new Error('error!!!')` 也被包裹成了 `return Promise.resolve(new Error('error!!!'))`，因此它会被 then 捕获而不是 catch。

### 10

```js
const promise = Promise.resolve().then(() => {
  return promise;
})
promise.catch(console.err)
```

```js
Uncaught (in promise) TypeError: Chaining cycle detected for promise #<Promise>
```

> `.then` 或 `.catch` 返回的值不能是 promise 本身，否则会造成死循环。

> 第一个 then 和第二个 then 中传入的都不是函数，一个是数字，一个是对象，因此发生了透传，将 `resolve(1)` 的值直接传到最后一个 then 里，直接打印出 1。

### 11

```js
Promise.reject('err!!!')
  .then((res) => {
    console.log('success', res)
  }, (err) => {
    console.log('error', err)
  }).catch(err => {
    console.log('catch', err)
  })
```

```js
error err!!!
```

> 在这道题中，错误直接被 `then` 的第二个参数捕获了，所以就不会被 `catch` 捕获了，输出结果为：`error err!!!'`

### 12

```js
Promise.resolve('1')
  .then(res => {
    console.log(res)
  })
  .finally(() => {
    console.log('finally')
  })
Promise.resolve('2')
  .finally(() => {
    console.log('finally2')
  	return '我是finally2返回的值'
  })
  .then(res => {
    console.log('finally2后面的then函数', res)
  })
```

```js
1
finally2
finally
finally2后面的then函数 2
```

- `.finally()` 方法不管 Promise 对象最后的状态如何都会执行
- `.finally()` 方法的回调函数不接受任何的参数，也就是说你在 `.finally()` 函数中是无法知道 Promise 最终的状态是 `resolved` 还是 `rejected` 的
- 它最终返回的默认会是一个上一次的 Promise 对象值，不过如果抛出的是一个异常则返回异常的 Promise 对象。
- finally 本质上是 then 方法的特例

### 13

```js
function runAsync (x) {
  const p = new Promise(r => setTimeout(() => r(x, console.log(x)), 1000))
  return p
}
function runReject (x) {
  const p = new Promise((res, rej) => setTimeout(() => rej(`Error: ${x}`, console.log(x)), 1000 * x))
  return p
}
Promise.all([runAsync(1), runReject(4), runAsync(3), runReject(2)])
       .then(res => console.log(res))
       .catch(err => console.log(err))
```

```js
// 1s后输出
1
3
// 2s后输出
2
Error: 2
// 4s后输出
4
```

> catch 捕获到了第一个错误，在这道题目中最先的错误就是 `runReject(2)` 的结果。如果一组异步操作中有一个异常都不会进入 `.then()` 的第一个回调函数参数中。会被 `.then()` 的第二个回调函数捕获。

### 14

```js
function runAsync (x) {
  const p = new Promise(r => setTimeout(() => r(x, console.log(x)), 1000))
  return p
}
Promise.race([runAsync(1), runAsync(2), runAsync(3)])
  .then(res => console.log('result: ', res))
  .catch(err => console.log(err))
```

```js
1
'result: ' 1
2
3
```

### 15

```js
function runAsync(x) {
  const p = new Promise(r =>
    setTimeout(() => r(x, console.log(x)), 1000)
  );
  return p;
}
function runReject(x) {
  const p = new Promise((res, rej) =>
    setTimeout(() => rej(`Error: ${x}`, console.log(x)), 1000 * x)
  );
  return p;
}
Promise.race([runReject(0), runAsync(1), runAsync(2), runAsync(3)])
  .then(res => console.log("result: ", res))
  .catch(err => console.log(err));
```

```js
0
Error: 0
1
2
3
```

> `all` 和 `race` 传入的数组中如果有会抛出异常的异步任务，那么只有最先抛出的错误会被捕获，并且是被 then 的第二个参数或者后面的 catch 捕获；但并不会影响数组中其它的异步任务的执行。

### 16

```js
async function async1() {
  console.log("async1 start");
  await async2();
  console.log("async1 end");
}
async function async2() {
  console.log("async2");
}
async1();
console.log('start')
```

```js
async1 start
async2
start
async1 end
```

1. 首先执行函数中的同步代码 `async1 start`，之后遇到了 `await`，它会阻塞 `async1` 后面代码的执行，因此会先去执行 `async2` 中的同步代码 `async2`，然后跳出 `async1`；
2. 跳出 `async1` 函数后，执行同步代码 `start`；
3. 在一轮宏任务全部执行完之后，再来执行 `await` 后面的内容 `async1 end`。

这里可以理解为 await 后面的语句相当于放到了 new Promise 中，下一行及之后的语句相当于放在 Promise.then 中。

### 17

```js
async function async1() {
  console.log("async1 start");
  await async2();
  console.log("async1 end");
  setTimeout(() => {
    console.log('timer1')
  }, 0)
}
async function async2() {
  setTimeout(() => {
    console.log('timer2')
  }, 0)
  console.log("async2");
}
async1();
setTimeout(() => {
  console.log('timer3')
}, 0)
console.log("start")
```

```js
async1 start
async2
start
async1 end
timer2
timer3
timer1
```

1. 首先进入 `async1`，打印出 `async1 start`；
2. 之后遇到 `async2`，进入 `async2`，遇到定时器 `timer2`，加入宏任务队列，之后打印 `async2`；
3. 由于 `async2` 阻塞了后面代码的执行，所以执行后面的定时器 `timer3`，将其加入宏任务队列，之后打印 `start`；
4. 然后执行 async2 后面的代码，打印出 `async1 end`，遇到定时器 timer1，将其加入宏任务队列；
5. 最后，宏任务队列有三个任务，先后顺序为 `timer2`，`timer3`，`timer1`，没有微任务，所以直接所有的宏任务按照先进先出的原则执行。

### 18

```js
async function async1 () {
  console.log('async1 start');
  await new Promise(resolve => {
    console.log('promise1')
  })
  console.log('async1 success');
  return 'async1 end'
}
console.log('srcipt start')
async1().then(res => console.log(res))
console.log('srcipt end')
```

```js
script start
async1 start
promise1
script end
```

> 这里需要注意的是在 `async1` 中 `await` 后面的 Promise 是没有返回值的，也就是它的状态始终是 `pending` 状态，所以在 `await` 之后的内容是不会执行的，包括 `async1` 后面的 `.then`。

### 19

```js
async function async1() {
  console.log("async1 start");
  await async2();
  console.log("async1 end");
}

async function async2() {
  console.log("async2");
}

console.log("script start");

setTimeout(function() {
  console.log("setTimeout");
}, 0);

async1();

new Promise(resolve => {
  console.log("promise1");
  resolve();
}).then(function() {
  console.log("promise2");
});
console.log('script end')
```

```js
script start
async1 start
async2
promise1
script end
async1 end
promise2
setTimeout
```

1. 开头定义了 async1 和 async2 两个函数，但是并未执行，执行 script 中的代码，所以打印出 script start；
2. 遇到定时器 Settimeout，它是一个宏任务，将其加入到宏任务队列；
3. 之后执行函数 async1，首先打印出 async1 start；
4. 遇到 await，执行 async2，打印出 async2，并阻断后面代码的执行，将后面的代码加入到微任务队列；
5. 然后跳出 async1 和 async2，遇到 Promise，打印出 promise1；
6. 遇到 resolve，将其加入到微任务队列，然后执行后面的 script 代码，打印出 script end；
7. 之后就该执行微任务队列了，首先打印出 async1 end，然后打印出 promise2；
8. 执行完微任务队列，就开始执行宏任务队列中的定时器，打印出 setTimeout。

```js
const p1 = new Promise((resolve) => {
  setTimeout(() => {
    resolve('resolve3');
    console.log('timer1')
  }, 0)
  resolve('resovle1');
  resolve('resolve2');
}).then(res => {
  console.log(res)  // resolve1
  setTimeout(() => {
    console.log(p1)
  }, 1000)
}).finally(res => {
  console.log('finally', res)
})
```

```js
resolve1
finally  undefined
timer1
Promise{<resolved>: undefined}
```

> 需要注意的是最后一个定时器打印出的 p1 其实是 `.finally` 的返回值，我们知道 `.finally` 的返回值如果在没有抛出错误的情况下默认会是上一个 Promise 的返回值，而这道题中 `.finally` 上一个 Promise 是 `.then()`，但是这个 `.then()` 并没有返回值，所以 p1 打印出来的 Promise 的值会是 `undefined`，如果在定时器的下面加上一个 `return 1`，则值就会变成 1。

### 20

```js
console.log('1');

setTimeout(function() {
    console.log('2');
    process.nextTick(function() {
        console.log('3');
    })
    new Promise(function(resolve) {
        console.log('4');
        resolve();
    }).then(function() {
        console.log('5')
    })
})
process.nextTick(function() {
    console.log('6');
})
new Promise(function(resolve) {
    console.log('7');
    resolve();
}).then(function() {
    console.log('8')
})

setTimeout(function() {
    console.log('9');
    process.nextTick(function() {
        console.log('10');
    })
    new Promise(function(resolve) {
        console.log('11');
        resolve();
    }).then(function() {
        console.log('12')
    })
})
```

```js
1
7
6
8
2
4
3
5
9
11
10
12
```

### 21

```js
Promise.resolve().then(() => {
    console.log('1');
    throw 'Error';
}).then(() => {
    console.log('2');
}).catch(() => {
    console.log('3');
    throw 'Error';
}).then(() => {
    console.log('4');
}).catch(() => {
    console.log('5');
}).then(() => {
    console.log('6');
});
```

```js
1 
3 
5 
6
```

> 在这道题目中，我们需要知道，无论是 then 还是 catch 中，只要 throw 抛出了错误，就会被 catch 捕获，如果没有 throw 出错误，就被继续执行后面的 then。

### 22

```js
Promise.resolve()
  .then(() => {
    console.log(0);
    return Promise.resolve(4);
  })
  .then((res) => {
    console.log(res);
  });
Promise.resolve()
  .then(() => {
    console.log(1);
  })
  .then(() => {
    console.log(2);
  })
  .then(() => {
    console.log(3);
  })
  .then(() => {
    console.log(5);
  })
  .then(() => {
    console.log(6);
  });
```

```js
0
1
2
3
4
5
6
```

> 如果 resolve() 的括号内的结果是一个 promise 的话，会多执行两个 `micro task`

```js
// 上面的代码等价于
new Promise(resolve => {
  console.log(0);
  resolve(4);
})
.then()
.then()
.then((res) => {
    console.log(res)
})
```

### 23

```js
var date = new Date();

console.log(1, new Date() - date);

setTimeout(() => {
  console.log(2, new Date() - date);
}, 500);

Promise.resolve().then(console.log(3, new Date() - date));

while (new Date() - date < 1000) {}

console.log(4, new Date() - date);
```

```js
1 0
3 1
4 1000
2 1000
```

1. 首先执行同步代码，输出 `1 0`
2. 遇到 `setTimeout` ，定时 `500ms` 后执行，此时，将 `setTimeout` 交给异步线程，主线程继续执行下一步，异步线程执行 `setTimeout`
3. 主线程执行 `Promise.resolve().then` , `.then` 的参数不是函数，发生传值调用，即在传递给 then 的时候，console 就已经执行了，输出 `3 1`
4. 主线程继续执行同步任务 `whlie` ，等待 `1000ms` ，在此期间，`setTimeout` 定时 `500ms` 完成，异步线程将 `setTimeout` 回调事件放入宏任务队列中
5. 继续执行下一步，输出 `4 1000`
6. 检查微任务队列，为空
7. 检查宏任务队列，执行 `setTimeout` 宏任务，输入 `2 1000`

## this

### 1

```js
function foo() {
  console.log( this.a );
}

function doFoo() {
  foo();
}

var obj = {
  a: 1,
  doFoo: doFoo
};

var a = 2; 
obj.doFoo()
```

```js
2
```

> 在 Javascript 中，this 指向函数执行时的当前对象。在执行 foo 的时候，执行环境就是 doFoo 函数，执行环境为全局。所以，foo 中的 this 是指向 window 的，所以会打印出 2。

### 2

```js
var a = 10
var obj = {
  a: 20,
  say: () => {
    console.log(this.a)
  }
}
obj.say() 

var anotherObj = { a: 30 } 
obj.say.apply(anotherObj) 
```

```js
10
10
```

> 箭头函数时不绑定 this 的，它的 this 来自原其父级所处的上下文，所以首先会打印全局中的 a 的值 10。后面虽然让 say 方法指向了另外一个对象，但是仍不能改变箭头函数的特性，它的 this 仍然是指向全局的，所以依旧会输出 10。

### 3

```js
var obj = { 
  name : 'cuggz', 
  fun : function(){ 
    console.log(this.name); 
  } 
} 
obj.fun()     // cuggz
new obj.fun() // undefined
```

> 使用 new 构造函数时，其 this 指向的是基于构造器的原型创建一个新的对象

### 4

```js
var obj = {
   say: function() {
     var f1 = () =>  {
       console.log("1111", this);
     }
     f1();
   },
   pro: {
     getPro:() =>  {
        console.log(this);
     }
   }
}
var o = obj.say;
o();
obj.say();
obj.pro.getPro();
```

```js
1111 window对象
1111 obj对象
window对象
```

- o()，o 是在全局执行的，而 f1 是箭头函数，它是没有绑定 this 的，它的 this 指向其父级的 this，其父级 say 方法的 this 指向的是全局作用域，所以会打印出 window；
- obj.say()，谁调用 say，say 的 this 就指向谁，所以此时 this 指向的是 obj 对象；
- obj.pro.getPro()，我们知道，箭头函数时不绑定 this 的，getPro 处于 pro 中，而对象不构成单独的作用域，所以箭头的函数的 this 就指向了全局作用域 window。

### 5

```js
var myObject = {
    foo: "bar",
    func: function() {
        var self = this;
        console.log(this.foo);  
        console.log(self.foo);  
        (function() {
            console.log(this.foo);  
            console.log(self.foo);  
        }());
    }
};
myObject.func();
```

```js
bar 
bar 
undefined 
bar
```

> 首先 func 是由 myObject 调用的，this 指向 myObject。又因为 var self = this; 所以 self 指向 myObject。
>
> 这个立即执行匿名函数表达式是由 window 调用的，this 指向 window 。立即执行匿名函数的作用域处于 myObject.func 的作用域中，在这个作用域找不到 self 变量，沿着作用域链向上查找 self 变量，找到了指向 myObject 对象的 self。

### 6

```js
window.number = 2;
var obj = {
 number: 3,
 db1: (function(){
   console.log(this);
   this.number *= 4;
   return function(){
     console.log(this);
     this.number *= 5;
   }
 })()
}
var db1 = obj.db1;
db1();
obj.db1();
console.log(obj.number);     
console.log(window.number);  
```

```js
window对象
window对象
obj对象
15
40
```

1. 执行 db1() 时，this 指向全局作用域，所以 window.number * 4 = 8，然后执行匿名函数， 所以 window.number * 5 = 40；
2. 执行 obj.db1(); 时，this 指向 obj 对象，执行匿名函数，所以 obj.numer * 5 = 15。

### 7

```js
var length = 10;
function fn() {
    console.log(this.length);
}
 
var obj = {
  length: 5,
  method: function(fn) {
    fn();
    arguments[0]();
  }
};
 
obj.method(fn, 1);
```

```js
10
2
```

1. 第一次执行 fn()，this 指向 window 对象，输出 10。
2. 第二次执行 `arguments[0]`，相当于 arguments 调用方法，this 指向 arguments，而这里传了两个参数，故输出 arguments 长度为 2。

### 8

```js
var a = 1;
function printA(){
  console.log(this.a);
}
var obj={
  a:2,
  foo:printA,
  bar:function(){
    printA();
  }
}

obj.foo(); // 2
obj.bar(); // 1
var foo = obj.foo;
foo(); // 1
```

```js
2
1
1
```

1. obj.foo()，foo 的 this 指向 obj 对象，所以 a 会输出 2；
2. obj.bar()，printA 在 bar 方法中执行，所以此时 printA 的 this 指向的是 window，所以会输出 1；
3. foo()，foo 是在全局对象中执行的，所以其 this 指向的是 window，所以会输出 1；

### 9

```js
var x = 3;
var y = 4;
var obj = {
    x: 1,
    y: 6,
    getX: function() {
        var x = 5;
        return function() {
            return this.x;
        }();
    },
    getY: function() {
        var y = 7;
        return this.y;
    }
}
console.log(obj.getX())
console.log(obj.getY())
```

```js
3
6
```

1. 我们知道，匿名函数的 this 是指向全局对象的，所以 this 指向 window，会打印出 3；
2. getY 是由 obj 调用的，所以其 this 指向的是 obj 对象，会打印出 6。

### 10

```js
 var a = 10; 
 var obt = { 
   a: 20, 
   fn: function(){ 
     var a = 30; 
     console.log(this.a)
   } 
 }
 obt.fn();
 obt.fn.call();
 (obt.fn)();
```

```js
20
10
20
```

-  obt.fn()，fn 是由 obt 调用的，所以其 this 指向 obt 对象，会打印出 20；
-  obt.fn.call()，这里 call 的参数啥都没写，就表示 null，我们知道如果 call 的参数为 undefined 或 null，那么 this 就会指向全局对象 this，所以会打印出 10；
-  (obt.fn)()， 这里给表达式加了括号，而括号的作用是改变表达式的运算顺序，而在这里加与不加括号并无影响；相当于  obt.fn()，所以会打印出 20；

### 11

```js
function a(xx){
  this.x = xx;
  return this
};
var x = a(5);
var y = a(6);

console.log(x.x)
console.log(y.x)
```

```js
undefined
6
```

- 最关键的就是 var x = a(5)，函数 a 是在全局作用域调用，所以函数内部的 this 指向 window 对象。**所以 this.x = 5 就相当于：window.x = 5**。之后 return this，也就是说 var x = a(5) 中的 x 变量的值是 window，这里的 x 将函数内部的 x 的值覆盖了。然后执行 console.log(x.x)， 也就是 console.log(window.x)，而 window 对象中没有 x 属性，所以会输出 undefined。
- 当指向 y.x 时，会给全局变量中的 x 赋值为 6，所以会打印出 6。

### 12

```js
function foo(something){
    this.a = something
}

var obj1 = {
    foo: foo
}

var obj2 = {}

obj1.foo(2); 
console.log(obj1.a);

obj1.foo.call(obj2, 3);
console.log(obj2.a);

var bar = new obj1.foo(4)
console.log(obj1.a);
console.log(bar.a);
```

```js
2
3
2
4
```

1. 首先执行 obj1.foo(2); 会在 obj 中添加 a 属性，其值为 2。之后执行 obj1.a，a 是右 obj1 调用的，所以 this 指向 obj，打印出 2；
2. 执行 obj1.foo.call(obj2, 3) 时，会将 foo 的 this 指向 obj2，后面就和上面一样了，所以会打印出 3；
3. obj1.a 会打印出 2；
4. 最后就是考察 this 绑定的优先级了，new 绑定是比隐式绑定优先级高，所以会输出 4。

### 12

```js
function foo() {
  console.log(this);
}
foo.call(3);
```

```js
"use strict";
function test() {
  console.log(this);
}
test.call(2); // 2
```

```js
function test() {
  console.log(this);
}
test.call(2); // Number {2}
```

> 如果处于非严格模式下，要绑定的 `this` 指定为 `null` 或 `undefined` 时会自动替换为全局对象，原始值则会被包装

## 作用域 & 变量提升 & 闭包

### 1

```js
(function(){
   var x = y = 1;
})();
var z;

console.log(y);
console.log(z);
console.log(x);
```

```js
1
undefined
Uncaught ReferenceError: x is not defined
```

> 这段代码的关键在于：var x = y = 1; 实际上这里是从右往左执行的，首先执行 y = 1, 因为 y 没有使用 var 声明，所以它是一个全局变量，然后第二步是将 y 赋值给 x，讲一个全局变量赋值给了一个局部变量，最终，x 是一个局部变量，y 是一个全局变量，所以打印 x 是报错。

### 2

```js
var friendName = 'World';
(function() {
  if (typeof friendName === 'undefined') {
    var friendName = 'Jack';
    console.log('Goodbye ' + friendName);
  } else {
    console.log('Hello ' + friendName);
  }
})();
```

```js
Goodbye Jack
```

> var 变量提升

### 3

```js
function fn1(){
  console.log('fn1')
}
var fn2
 
fn1()
fn2()
 
fn2 = function() {
  console.log('fn2')
}
 
fn2()
```

```js
fn1
Uncaught TypeError: fn2 is not a function
fn2
```

> 这里也是在考察变量提升，关键在于第一个 fn2()，这时 fn2 仍是一个 undefined 的变量，所以会报错 fn2 不是一个函数。

### 4

```js
function a() {
  var temp = 10;
  b();
}

function b() {
  console.log(temp);
}

a();
```

```js
报错 Uncaught ReferenceError: temp is not defined
```

> js 中变量的作用域链与定义时的环境有关，与执行时无关。temp 是 a 函数中的局部变量

### 5

```js
function fun(n, o) {
  console.log(o)
  return {
    fun: function(m){
      return fun(m, n);
    }
  };
}
var a = fun(0);  a.fun(1);  a.fun(2);  a.fun(3);
var b = fun(0).fun(1).fun(2).fun(3);
var c = fun(0).fun(1);  c.fun(2);  c.fun(3);
```

```js
undefined  0  0  0
undefined  0  1  2
undefined  0  1  1
```

> 这是一道关于闭包的题目，对于 fun 方法，调用之后返回的是一个对象。我们知道，当调用函数的时候传入的实参比函数声明时指定的形参个数要少，剩下的形参都将设置为 undefined 值。所以 `console.log(o);` 会输出 undefined。而 a 就是是 fun(0) 返回的那个对象。也就是说，函数 fun 中参数 n 的值是 0，而返回的那个对象中，需要一个参数 n，而这个对象的作用域中没有 n，它就继续沿着作用域向上一级的作用域中寻找 n，最后在函数 fun 中找到了 n，n 的值是 0。了解了这一点，其他运算就很简单了，以此类推。

### 6

```js
f = function() {return true;};   
g = function() {return false;};   
(function() {   
   if (g() && [] == ![]) {   
      f = function f() {return false;};   
      function g() {return true;}   
   }   
})();   
console.log(f());
```

```js
false
```

这里首先定义了两个变量 f 和 g，我们知道变量是可以重新赋值的。后面是一个匿名自执行函数，在 if 条件中调用了函数 g()，由于在匿名函数中，又重新定义了函数 g，就覆盖了外部定义的变量 g，所以，这里调用的是内部函数 g 方法，返回为 true。第一个条件通过，进入第二个条件。

第二个条件是 [] == ![]，先看 ![] ，在 JavaScript 中，当用于布尔运算时，比如在这里，对象的非空引用被视为 true，空引用 null 则被视为 false。由于这里不是一个 null, 而是一个没有元素的数组，所以 [] 被视为 true, 而 ![] 的结果就是 false 了。当一个布尔值参与到条件运算的时候，true 会被看作 1, 而 false 会被看作 0。现在条件变成了 [] == 0 的问题了，当一个对象参与条件比较的时候，它会被求值，求值的结果是数组成为一个字符串，[] 的结果就是 '' ，而 '' 会被当作 0 ，所以，条件成立。

两个条件都成立，所以会执行条件中的代码， f 在定义是没有使用 var，所以他是一个全局变量。因此，这里会通过闭包访问到外部的变量 f, 重新赋值，现在执行 f 函数返回值已经成为 false 了。而 g 则不会有这个问题，这里是一个函数内定义的 g，不会影响到外部的 g 函数。所以最后的结果就是 false。

### 7

```js
for (var i = 0; i < 5; i++) {
  setTimeout(() => console.log(i), 1000);
}
```

一秒之后连续输出五个 5

```js
// 正确写法
for (let i = 0; i < 5; i++) {
  setTimeout(() => console.log(i), 1000 * i);
}
for (var i = 0; i < 5; i++) {
  setTimeout(console.log, 1000 * i, i);
}
```

### 8

```js
var a = 3
let a
```

> 暂时性死区，报错

### 9

```js
var x = 1;

function foo(x = x) {
  // ...
}

foo() // ReferenceError: Cannot access 'x' before initialization
```

> 参数 `x = x` 形成一个单独作用域。实际执行的是 `let x = x`，由于暂时性死区的原因，这行代码会报错。

## 原型 & 继承

### 1

```js
function Person(name) {
    this.name = name
}
var p2 = new Person('king');
console.log(p2.__proto__) //Person.prototype
console.log(p2.__proto__.__proto__) //Object.prototype
console.log(p2.__proto__.__proto__.__proto__) // null
console.log(p2.__proto__.__proto__.__proto__.__proto__)//null后面没有了，报错
console.log(p2.__proto__.__proto__.__proto__.__proto__.__proto__)//null后面没有了，报错
console.log(p2.constructor)//Person
console.log(p2.prototype)//undefined p2是实例，没有prototype属性
console.log(Person.constructor)//Function 一个空函数
console.log(Person.prototype)//打印出Person.prototype这个对象里所有的方法和属性
console.log(Person.prototype.constructor)//Person
console.log(Person.prototype.__proto__)// Object.prototype
console.log(Person.__proto__) //Function.prototype
console.log(Function.prototype.__proto__)//Object.prototype
console.log(Function.__proto__)//Function.prototype
console.log(Object.__proto__)//Function.prototype
console.log(Object.prototype.__proto__)//null
```

### 2

```js
// a
function Foo () {
 getName = function () {
   console.log(1);
 }
 return this;
}
// b
Foo.getName = function () {
 console.log(2);
}
// c
Foo.prototype.getName = function () {
 console.log(3);
}
// d
var getName = function () {
 console.log(4);
}
// e
function getName () {
 console.log(5);
}

Foo.getName();           
getName();               
Foo().getName();         
getName();             
new Foo.getName();       
new Foo().getName();    
new new Foo().getName();
```

```js
2
4
1
1
2
3
3
```

- `Foo.getName()`，Foo 为一个函数对象，对象都可以有属性，b 处定义 Foo 的 getName 属性为函数，输出 2；
- `getName()`，这里看 d、e 处，d 为函数表达式，e 为函数声明，两者区别在于变量提升，函数声明的 5 会被后边函数表达式的 4 覆盖；
-  `Foo().getName()`， 这里要看 a 处，在 Foo 内部将全局的 getName 重新赋值为 console.log(1) 的函数，执行 Foo() 返回 this，这个 this 指向 window，Foo().getName() 即为 window.getName()，输出 1；
- `getName()`， 上面 3 中，全局的 getName 已经被重新赋值，所以这里依然输出 1；
- `new Foo.getName()`，这里等价于 new (Foo.getName())，先执行 Foo.getName()，输出 2，然后 new 一个实例；
- `new Foo().getName()`， 这 里等价于 (new Foo()).getName(), 先 new 一个 Foo 的实例，再执行这个实例的 getName 方法，但是这个实例本身没有这个方法，所以去原型链 `__protot__` 上边找，`实例.protot` === Foo.prototype，所以输出 3；
- `new new Foo().getName()`， 这里等价于 new (new Foo().getName())，如上述 6，先输出 3，然后 new 一个 new Foo().getName() 的实例。

### 3

```js
var F = function() {};
Object.prototype.a = function() {
  console.log('a');
};
Function.prototype.b = function() {
  console.log('b');
}
var f = new F();
f.a();
f.b();
F.a();
F.b()
```

```js
a
Uncaught TypeError: f.b is not a function
a
b
```

- f 并不是 Function 的实例，因为它本来就不是构造函数，调用的是 Function 原型链上的相关属性和方法，只能访问到 Object 原型链。所以 f.a() 输出 a  ，而 f.b() 就报错了。
- F 是个构造函数，而 F 是构造函数 Function 的一个实例。因为 F instanceof  Object === true，F instanceof Function === true，由此可以得出结论：F 是 Object 和 Function 两个的实例，即 F 能访问到 a， 也能访问到 b。所以 F.a() 输出 a ，F.b() 输出 b。

### 4

```js
function Foo(){
    Foo.a = function(){
        console.log(1);
    }
    this.a = function(){
        console.log(2)
    }
}

Foo.prototype.a = function(){
    console.log(3);
}

Foo.a = function(){
    console.log(4);
}

Foo.a();
let obj = new Foo();
obj.a();
Foo.a();
```

```js
4
2
1
```

- Foo.a() 这个是调用 Foo 函数的静态方法 a，虽然 Foo 中有优先级更高的属性方法 a，但 Foo 此时没有被调用，所以此时输出 Foo 的静态方法 a 的结果：4
- let obj = new Foo(); 使用了 new 方法调用了函数，返回了函数实例对象，此时 Foo 函数内部的属性方法初始化，原型链建立。
- obj.a() ; 调用 obj 实例上的方法 a，该实例上目前有两个 a 方法：一个是内部属性方法，另一个是原型上的方法。当这两者都存在时，首先查找 ownProperty ，如果没有才去原型链上找，所以调用实例上的 a 输出：2
- Foo.a() ; 根据第 2 步可知 Foo 函数内部的属性方法已初始化，覆盖了同名的静态方法，所以输出：1

### 5

```js
var A = {n: 4399};
var B =  function(){this.n = 9999};
var C =  function(){var n = 8888};
B.prototype = A;
C.prototype = A;
var b = new B();
var c = new C();
A.n++
console.log(b.n);
console.log(c.n);
```

```js
9999
4400
```

1. console.log(b.n)，在查找 b.n 是首先查找 b 对象自身有没有 n 属性，如果没有会去原型（prototype）上查找，当执行 var b = new B() 时，函数内部 this.n=9999(此时 this 指向 b) 返回 b 对象，b 对象有自身的 n 属性，所以返回 9999。
2. console.log(c.n)，同理，当执行 var c = new C() 时，c 对象没有自身的 n 属性，向上查找，找到原型 （prototype）上的 n 属性，因为 A.n++(此时对象 A 中的 n 为 4400)， 所以返回 4400。

### 6

```js
function Parent() {
    this.a = 1;
    this.b = [1, 2, this.a];
    this.c = { demo: 5 };
    this.show = function () {
        console.log(this.a , this.b , this.c.demo );
    }
}

function Child() {
    this.a = 2;
    this.change = function () {
        this.b.push(this.a);
        this.a = this.b.length;
        this.c.demo = this.a++;
    }
}

Child.prototype = new Parent();
var parent = new Parent();
var child1 = new Child();
var child2 = new Child();
child1.a = 11;
child2.a = 12;
parent.show();
child1.show();
child2.show();
child1.change();
child2.change();
parent.show();
child1.show();
child2.show();
```

```js
parent.show(); // 1  [1,2,1] 5

child1.show(); // 11 [1,2,1] 5
child2.show(); // 12 [1,2,1] 5

parent.show(); // 1 [1,2,1] 5

child1.show(); // 5 [1,2,1,11,12] 5

child2.show(); // 6 [1,2,1,11,12] 5
```

## 其他

### 1

```js
[] == "";
// 1. [].toString() => ""
// 2. "" == ""
// 3. Number("") => 0
// 4. 0 == 0 => true

[3] == 3;
// 1. [3].toString() => "3"
// 2. "3" == 3
// 3. Number("3") => 3
// 4. 3 == 3 => true

[] == false;
// 1. [].toString() => ""
// 2. "" == false
// 3. Number("") => 0   Number(false) => 0
// 4. 0 == 0 => true

42 == true;
// 1. Number(true) => 1
// 2. 42 == 1 => false
```

![[Pasted image 20240121203707.png]]
